Workbook

Sheet Riepilogo
B2: Piano Installazioni DAE — Poste Italiane
B3: Nihon Kohden Europe GmbH · Piano Installazioni v1.0 · Emesso il 20/07/2026
B5: DATI GENERALI
B6: Sedi totali | C6: =SUM(Calendario!K2:K254) -> 244
B7: DAE totali | C7: =SUM(Calendario!I2:I254) -> 839
B8: Prima installazione | C8: =MIN(Calendario!A2:A254) -> 46230
B9: Ultima installazione | C9: =MAX(Calendario!A2:A254) -> 46318
B10: Giornate di installazione | C10: =SUMPRODUCT(1/COUNTIFS(Calendario!A2:A254,Calendario!A2:A254&"")) -> 56
B13: RIPARTIZIONE PER SQUADRA
B14: Tecnico | C14: Sedi | D14: DAE | E14: Dal | F14: Al
B15: Pilota | C15: =SUMIFS(Calendario!K2:K254,Calendario!B2:B254,B15) -> 8 | D15: =SUMIFS(Calendario!I2:I254,Calendario!B2:B254,B15) -> 90 | E15: =_xlfn.MINIFS(Calendario!A2:A254,Calendario!B2:B254,B15) -> 46230 | F15: =_xlfn.MAXIFS(Calendario!A2:A254,Calendario!B2:B254,B15) -> 46233
B16: Tecnico A | C16: =SUMIFS(Calendario!K2:K254,Calendario!B2:B254,B16) -> 91 | D16: =SUMIFS(Calendario!I2:I254,Calendario!B2:B254,B16) -> 305 | E16: =_xlfn.MINIFS(Calendario!A2:A254,Calendario!B2:B254,B16) -> 46251 | F16: =_xlfn.MAXIFS(Calendario!A2:A254,Calendario!B2:B254,B16) -> 46317
B17: Tecnico B | C17: =SUMIFS(Calendario!K2:K254,Calendario!B2:B254,B17) -> 103 | D17: =SUMIFS(Calendario!I2:I254,Calendario!B2:B254,B17) -> 287 | E17: =_xlfn.MINIFS(Calendario!A2:A254,Calendario!B2:B254,B17) -> 46238 | F17: =_xlfn.MAXIFS(Calendario!A2:A254,Calendario!B2:B254,B17) -> 46318
B18: Tecnico C | C18: =SUMIFS(Calendario!K2:K254,Calendario!B2:B254,B18) -> 42 | D18: =SUMIFS(Calendario!I2:I254,Calendario!B2:B254,B18) -> 157 | E18: =_xlfn.MINIFS(Calendario!A2:A254,Calendario!B2:B254,B18) -> 46251 | F18: =_xlfn.MAXIFS(Calendario!A2:A254,Calendario!B2:B254,B18) -> 46317
B19: TOTALE | C19: =SUM(C15:C18) -> 244 | D19: =SUM(D15:D18) -> 839
B22: INFORMAZIONI TECNICI
B23: Tecnico | C23: Nome | D23: Telefono | E23: Targa
B24: Tecnico A | C24: Bruno Guimaraes Reis | D24: 378 3065974 | E24: GD285XS
B25: Tecnico B | C25: Ricardo De Oliveira Mello | D25: 378 3091424 | E25: GJ018JR
B26: Tecnico C | C26: Antonio Forte | D26: 3470874462 | E26: HC655YN
B30: DAE PER MESE
B31: Mese | C31: DAE | D31: Sedi (prima visita)
B32: Luglio 2026 | C32: =SUMIFS(Calendario!I2:I254,Calendario!A2:A254,">="&DATE(2026,7,1),Calendario!A2:A254,"<"&DATE(2026,8,1)) -> 90 | D32: =SUMIFS(Calendario!K2:K254,Calendario!A2:A254,">="&DATE(2026,7,1),Calendario!A2:A254,"<"&DATE(2026,8,1)) -> 8
B33: Agosto 2026 | C33: =SUMIFS(Calendario!I2:I254,Calendario!A2:A254,">="&DATE(2026,8,1),Calendario!A2:A254,"<"&DATE(2026,9,1)) -> 216 | D33: =SUMIFS(Calendario!K2:K254,Calendario!A2:A254,">="&DATE(2026,8,1),Calendario!A2:A254,"<"&DATE(2026,9,1)) -> 70
B34: Settembre 2026 | C34: =SUMIFS(Calendario!I2:I254,Calendario!A2:A254,">="&DATE(2026,9,1),Calendario!A2:A254,"<"&DATE(2026,10,1)) -> 348 | D34: =SUMIFS(Calendario!K2:K254,Calendario!A2:A254,">="&DATE(2026,9,1),Calendario!A2:A254,"<"&DATE(2026,10,1)) -> 106
B35: Ottobre 2026 | C35: =SUMIFS(Calendario!I2:I254,Calendario!A2:A254,">="&DATE(2026,10,1),Calendario!A2:A254,"<"&DATE(2026,11,1)) -> 185 | D35: =SUMIFS(Calendario!K2:K254,Calendario!A2:A254,">="&DATE(2026,10,1),Calendario!A2:A254,"<"&DATE(2026,11,1)) -> 60
B36: TOTALE | C36: =SUM(C32:C35) -> 839 | D36: =SUM(D32:D35) -> 244
B39: DAE PER GRUPPO
B40: Gruppo | C40: DAE | D40: Sedi
B41: PLOG | C41: =SUMIFS(Calendario!I2:I254,Calendario!H2:H254,B41) -> 74 | D41: =SUMIFS(Calendario!K2:K254,Calendario!H2:H254,B41) -> 9
B42: Poste Italiane | C42: =SUMIFS(Calendario!I2:I254,Calendario!H2:H254,B42) -> 626 | D42: =SUMIFS(Calendario!K2:K254,Calendario!H2:H254,B42) -> 163
B43: Postel | C43: =SUMIFS(Calendario!I2:I254,Calendario!H2:H254,B43) -> 10 | D43: =SUMIFS(Calendario!K2:K254,Calendario!H2:H254,B43) -> 4
B44: SDA | C44: =SUMIFS(Calendario!I2:I254,Calendario!H2:H254,B44) -> 129 | D44: =SUMIFS(Calendario!K2:K254,Calendario!H2:H254,B44) -> 68
B45: TOTALE | C45: =SUM(C41:C44) -> 839 | D45: =SUM(D41:D44) -> 244
B47: Nota: il conteggio sedi considera la prima giornata di intervento per ciascuna sede (le sedi con installazione su più giornate sono contate una sola volta).

Sheet Calendario
A1: Data | B1: Tecnico | C1: ID Sede | D1: Identificativo Stabile | E1: Regione | F1: Comune | G1: Indirizzo | H1: Gruppo | I1: N. DAE | J1: Fascia Oraria | K1: PrimaVisita
A2: 46230 | B2: Pilota | C2: 099 - ROMA | D2: 10415 | E2: LAZIO | F2: ROMA | G2: Viale Giuseppe Mazzini 101, Roma | H2: Poste Italiane | I2: 3 | J2: 15:00-18:00 | K2: =IF(COUNTIFS($C$2:C2,C2)=1,1,0) -> 1
A3: 46230 | B3: Pilota | C3: 191 - ROMA | D3: 301358 | E3: LAZIO | F3: ROMA | G3: Via Del Maggiolino 34/36, Roma | H3: Poste Italiane | I3: 1 | J3: 14:00-15:00 | K3: =IF(COUNTIFS($C$2:C3,C3)=1,1,0) -> 1
A4: 46231 | B4: Pilota | C4: 001 - ROMA | D4: 10365 | E4: LAZIO | F4: ROMA | G4: Viale Europa 175, Roma | H4: Poste Italiane | I4: 42 | J4: 08:00-20:00 | K4: =IF(COUNTIFS($C$2:C4,C4)=1,1,0) -> 1
A5: 46232 | B5: Pilota | C5: 005 - ROMA | D5: 10366 | E5: LAZIO | F5: ROMA | G5: Viale Europa 190, Roma | H5: Poste Italiane | I5: 25 | J5: 08:00-18:00 | K5: =IF(COUNTIFS($C$2:C5,C5)=1,1,0) -> 1
A6: 46232 | B6: Pilota | C6: 063 - ROMA | D6: 302713 | E6: LAZIO | F6: ROMA | G6: Via Lungotevere Flaminio 67, Roma | H6: Poste Italiane | I6: 4 | J6: 15:00-18:00 | K6: =IF(COUNTIFS($C$2:C6,C6)=1,1,0) -> 1
A7: 46233 | B7: Pilota | C7: 013 - ROMA | D7: 10297 | E7: LAZIO | F7: ROMA | G7: Viale Asia 90, Roma | H7: Poste Italiane | I7: 7 | J7: 14:00-18:00 | K7: =IF(COUNTIFS($C$2:C7,C7)=1,1,0) -> 1
A8: 46233 | B8: Pilota | C8: 021 - FIUMICINO | D8: 10176 | E8: LAZIO | F8: FIUMICINO | G8: Via Gino Cappannini 2, Fiumicino | H8: Poste Italiane | I8: 6 | J8: 10:00-16:00 | K8: =IF(COUNTIFS($C$2:C8,C8)=1,1,0) -> 1
A9: 46233 | B9: Pilota | C9: 179 - ROMA | D9: FIL. ROMA 4 | E9: LAZIO | F9: ROMA | G9: Viale delle Arti 119, Roma | H9: SDA | I9: 2 | J9: 16:00-18:00 | K9: =IF(COUNTIFS($C$2:C9,C9)=1,1,0) -> 1
A10: 46238 | B10: Tecnico B | C10: 010 - FARA IN SABINA | D10: FARA IN SABINA | E10: LAZIO | F10: FARA IN SABINA | G10: Via della Chimica, Passo Corese, Fara in Sabina (RI) | H10: PLOG | I10: 2 | J10: 13:30-18:00 | K10: =IF(COUNTIFS($C$2:C10,C10)=1,1,0) -> 1
A11: 46238 | B11: Tecnico B | C11: 190 - RIETI | D11: 10026 | E11: LAZIO | F11: RIETI | G11: Via Tancia 62, Rieti | H11: Poste Italiane | I11: 1 | J11: 11:00-12:00 | K11: =IF(COUNTIFS($C$2:C11,C11)=1,1,0) -> 1
A12: 46238 | B12: Tecnico B | C12: 193 - VITERBO | D12: 302179 | E12: LAZIO | F12: VITERBO | G12: Via dell'Industria 57, Viterbo | H12: Poste Italiane | I12: 1 | J12: 08:00-09:00 | K12: =IF(COUNTIFS($C$2:C12,C12)=1,1,0) -> 1
A13: 46239 | B13: Tecnico B | C13: 145 - ROMA | D13: 10285 | E13: LAZIO | F13: ROMA | G13: Via Affile 103, Roma | H13: Poste Italiane | I13: 2 | J13: 16:00-18:00 | K13: =IF(COUNTIFS($C$2:C13,C13)=1,1,0) -> 1
... A19: 46241 | B19: Tecnico B | C19: 010 - FARA IN SABINA | D19: FARA IN SABINA | E19: LAZIO | F19: FARA IN SABINA | G19: Via della Chimica, Passo Corese, Fara in Sabina (RI) | H19: PLOG | I19: 6 | J19: 08:00-12:00 | K19: =IF(COUNTIFS($C$2:C19,C19)=1,1,0) -> 0
A20: 46251 | B20: Tecnico C | C20: 061 - TARANTO | D20: 11441 | E20: PUGLIA | F20: TARANTO | G20: Via Giovinazzi Ciro 78, Taranto | H20: Poste Italiane | I20: 4 | J20: 09:30-15:30 | K20: 1
A21: 46251 | B21: Tecnico A | C21: 019 - VERONA | D21: 13472 | E21: VENETO | F21: VERONA | G21: Via delle Coste, Verona | H21: Poste Italiane | I21: 6 | J21: 10:00-13:30 | K21: =IF(COUNTIFS($C$2:C21,C21)=1,1,0) -> 1
A22: 46251 | B22: Tecnico B | C22: 113 - PISTOIA | D22: 9241 | E22: TOSCANA | F22: PISTOIA | G22: Via Pratese 49, Pistoia | H22: Poste Italiane | I22: 3 | J22: 13:00-15:00 | K22: =IF(COUNTIFS($C$2:C22,C22)=1,1,0) -> 1
A23: 46251 | B23: Tecnico B | C23: 127 - FIRENZE | D23: 4424 | E23: TOSCANA | F23: FIRENZE | G23: Via della Casella 17, Firenze | H23: Poste Italiane | I23: 2 | J23: 15:30-17:00 | K23: =IF(COUNTIFS($C$2:C23,C23)=1,1,0) -> 1
A24: 46251 | B24: Tecnico C | C24: 202 - TARANTO | D24: 302772 | E24: PUGLIA | F24: TARANTO | G24: Via Angelini Vito, Taranto | H24: Poste Italiane | I24: 1 | J24: 16:00-18:00 | K24: 1
A25: 46252 | B25: Tecnico B | C25: 009 - SESTO FIORENTINO | D25: 14730 | E25: TOSCANA | F25: SESTO FIORENTINO | G25: Via Pier Paolo Pasolini 397, Sesto Fiorentino | H25: Poste Italiane | I25: 9 | J25: 11:30-18:00 | K25: =IF(COUNTIFS($C$2:C25,C25)=1,1,0) -> 1
A26: 46252 | B26: Tecnico A | C26: 029 - VERONA | D26: 13510 | E26: VENETO | F26: VERONA | G26: Piazzale XXV Aprile 4/A, Verona | H26: Poste Italiane | I26: 6 | J26: 09:00-12:30 | K26: =IF(COUNTIFS($C$2:C26,C26)=1,1,0) -> 1
A27: 46252 | B27: Tecnico C | C27: 006 - BARI | D27: 964 | E27: PUGLIA | F27: BARI | G27: Via Amendola Giovanni 116, Bari | H27: Poste Italiane | I27: 6 | J27: 09:00-18:00 | K27: 1
A28: 46252 | B28: Tecnico B | C28: 110 - FIRENZE | D28: 4441 | E28: TOSCANA | F28: FIRENZE | G28: Via del Mezzetta, Firenze | H28: Poste Italiane | I28: 3 | J28: 08:30-10:30 | K28: =IF(COUNTIFS($C$2:C28,C28)=1,1,0) -> 1
A29: 46252 | B29: Tecnico A | C29: 183 - VERONA | D29: FIL. VERONA | E29: VENETO | F29: VERONA | G29: Strada dell'Alpo 54/A, Verona | H29: SDA | I29: 2 | J29: 14:00-15:30 | K29: =IF(COUNTIFS($C$2:C29,C29)=1,1,0) -> 1
A30: 46252 | B30: Tecnico A | C30: 185 - VERONA | D30: VERONA | E30: VENETO | F30: VERONA | G30: Via dell'Elettronica 6, Verona | H30: Postel | I30: 2 | J30: 16:00-17:30 | K30: =IF(COUNTIFS($C$2:C30,C30)=1,1,0) -> 1
A31: 46253 | B31: Tecnico B | C31: 018 - FIRENZE | D31: 4444 | E31: TOSCANA | F31: FIRENZE | G31: Piazza Davanzati 4, Firenze | H31: Poste Italiane | I31: 6 | J31: 13:30-17:00 | K31: =IF(COUNTIFS($C$2:C31,C31)=1,1,0) -> 1
A32: 46253 | B32: Tecnico C | C32: 006 - BARI | D32: 964 | E32: PUGLIA | F32: BARI | G32: Via Amendola Giovanni 116, Bari | H32: Poste Italiane | I32: 4 | J32: 09:00-14:00 | K32: 0
A33: 46253 | B33: Tecnico B | C33: 048 - PRATO | D33: 9530 | E33: TOSCANA | F33: PRATO | G33: Via Arcivescovo Antonio Martini 54, Prato | H33: Poste Italiane | I33: 5 | J33: 08:30-11:30 | K33: =IF(COUNTIFS($C$2:C33,C33)=1,1,0) -> 1
A34: 46253 | B34: Tecnico A | C34: 049 - PADOVA | D34: 8027 | E34: VENETO | F34: PADOVA | G34: Via della Ricerca Scientifica 5, Padova | H34: Poste Italiane | I34: 6 | J34: 13:30-17:00 | K34: =IF(COUNTIFS($C$2:C34,C34)=1,1,0) -> 1
A35: 46253 | B35: Tecnico C | C35: 162 - LECCE | D35: 5749 | E35: PUGLIA | F35: LECCE | G35: Via Lequile 10, Lecce | H35: Poste Italiane | I35: 2 | J35: 15:00-18:00 | K35: 1
A36: 46253 | B36: Tecnico A | C36: 206 - VICENZA | D36: 13797 | E36: VENETO | F36: VICENZA | G36: Strada Molini 51, Vicenza | H36: Poste Italiane | I36: 1 | J36: 09:30-10:30 | K36: =IF(COUNTIFS($C$2:C36,C36)=1,1,0) -> 1
A37: 46253 | B37: Tecnico A | C37: 243 - VICENZA | D37: FIL. VICENZA | E37: VENETO | F37: VICENZA | G37: Via Cuminello 20, Vicenza | H37: SDA | I37: 1 | J37: 11:00-12:00 | K37: =IF(COUNTIFS($C$2:C37,C37)=1,1,0) -> 1
A38: 46254 | B38: Tecnico A | C38: 028 - VENEZIA | D38: 13118 | E38: VENETO | F38: VENEZIA | G38: Via Torino 88, Venezia Mestre | H38: Poste Italiane | I38: 6 | J38: 14:00-17:30 | K38: =IF(COUNTIFS($C$2:C38,C38)=1,1,0) -> 1
A39: 46254 | B39: Tecnico B | C39: 047 - FIRENZE | D39: 16051 | E39: TOSCANA | F39: FIRENZE | G39: Via Francesco Geminiani, Firenze | H39: Poste Italiane | I39: 5 | J39: 08:30-11:30 | K39: =IF(COUNTIFS($C$2:C39,C39)=1,1,0) -> 1
A40: 46254 | B40: Tecnico C | C40: 046 - MODUGNO | D40: 970 | E40: PUGLIA | F40: MODUGNO | G40: Statale Provinciale 54 Snc, Modugno | H40: Poste Italiane | I40: 4 | J40: 09:00-13:00 | K40: 1
A41: 46254 | B41: Tecnico A | C41: 115 - VENEZIA | D41: 13091 | E41: VENETO | F41: VENEZIA | G41: Viale Alvise Ca' da Mosto 2, Venezia Mestre | H41: Poste Italiane | I41: 3 | J41: 10:30-12:30 | K41: =IF(COUNTIFS($C$2:C41,C41)=1,1,0) -> 1
A42: 46254 | B42: Tecnico C | C42: 046 - MODUGNO | D42: 970 | E42: PUGLIA | F42: MODUGNO | G42: Statale Provinciale 54 Snc, Modugno | H42: Poste Italiane | I42: 2 | J42: 15:00-18:00 | K42: 0
A43: 46255 | B43: Tecnico C | C43: 087 - FOGGIA | D43: 4582 | E43: PUGLIA | F43: FOGGIA | G43: Viale Xxiv Maggio 26, Foggia | H43: Poste Italiane | I43: 3 | J43: 09:00-13:00 | K43: =IF(COUNTIFS($C$2:C43,C43)=1,1,0) -> 1
A44: 46255 | B44: Tecnico C | C44: 161 - FOGGIA | D44: 4577 | E44: PUGLIA | F44: FOGGIA | G44: Via Motta Della Regina Snc, Foggia | H44: Poste Italiane | I44: 2 | J44: 15:00-18:00 | K44: =IF(COUNTIFS($C$2:C44,C44)=1,1,0) -> 1
A45: 46255 | B45: Tecnico A | C45: 225 - PADOVA | D45: PADOVA HUB | E45: VENETO | F45: PADOVA | G45: Via Visco, 1, 35010 Limena PD | H45: SDA | I45: 1 | J45: 10:00-11:00 | K45: =IF(COUNTIFS($C$2:C45,C45)=1,1,0) -> 1
...

Sheet Pilota
A1: Data | B1: ID Sede | C1: Identificativo Stabile | D1: Regione | E1: Comune | F1: Indirizzo | G1: Gruppo | H1: N. DAE | I1: Fascia Oraria
A2: 46230 | B2: 099 - ROMA | C2: 10415 | D2: LAZIO | E2: ROMA | F2: Viale Giuseppe Mazzini 101, Roma | G2: Poste Italiane | H2: 3 | I2: 15:00-18:00
A3: 46230 | B3: 191 - ROMA | C3: 301358 | D3: LAZIO | E3: ROMA | F3: Via Del Maggiolino 34/36, Roma | G3: Poste Italiane | H3: 1 | I3: 14:00-15:00
A4: 46231 | B4: 001 - ROMA | C4: 10365 | D4: LAZIO | E4: ROMA | F4: Viale Europa 175, Roma | G4: Poste Italiane | H4: 42 | I4: 08:00-20:00
A5: 46232 | B5: 005 - ROMA | C5: 10366 | D5: LAZIO | E5: ROMA | F5: Viale Europa 190, Roma | G5: Poste Italiane | H5: 25 | I5: 08:00-18:00
A6: 46232 | B6: 063 - ROMA | C6: 302713 | D6: LAZIO | E6: ROMA | F6: Via Lungotevere Flaminio 67, Roma | G6: Poste Italiane | H6: 4 | I6: 15:00-18:00
A7: 46233 | B7: 013 - ROMA | C7: 10297 | D7: LAZIO | E7: ROMA | F7: Viale Asia 90, Roma | G7: Poste Italiane | H7: 7 | I7: 14:00-18:00
A8: 46233 | B8: 021 - FIUMICINO | C8: 10176 | D8: LAZIO | E8: FIUMICINO | F8: Via Gino Cappannini 2, Fiumicino | G8: Poste Italiane | H8: 6 | I8: 10:00-16:00
A9: 46233 | B9: 179 - ROMA | C9: FIL. ROMA 4 | D9: LAZIO | E9: ROMA | F9: Viale delle Arti 119, Roma | G9: SDA | H9: 2 | I9: 16:00-18:00

Sheet Tecnico A
A1: Data | B1: ID Sede | C1: Identificativo Stabile | D1: Regione | E1: Comune | F1: Indirizzo | G1: Gruppo | H1: N. DAE | I1: Fascia Oraria
A2: 46251 | B2: 019 - VERONA | C2: 13472 | D2: VENETO | E2: VERONA | F2: Via delle Coste, Verona | G2: Poste Italiane | H2: 6 | I2: 10:00-13:30
A3: 46252 | B3: 029 - VERONA | C3: 13510 | D3: VENETO | E3: VERONA | F3: Piazzale XXV Aprile 4/A, Verona | G3: Poste Italiane | H3: 6 | I3: 09:00-12:30
A4: 46252 | B4: 183 - VERONA | C4: FIL. VERONA | D4: VENETO | E4: VERONA | F4: Strada dell'Alpo 54/A, Verona | G4: SDA | H4: 2 | I4: 14:00-15:30
A5: 46252 | B5: 185 - VERONA | C5: VERONA | D5: VENETO | E5: VERONA | F5: Via dell'Elettronica 6, Verona | G5: Postel | H5: 2 | I5: 16:00-17:30
A6: 46253 | B6: 049 - PADOVA | C6: 8027 | D6: VENETO | E6: PADOVA | F6: Via della Ricerca Scientifica 5, Padova | G6: Poste Italiane | H6: 6 | I6: 13:30-17:00
A7: 46253 | B7: 206 - VICENZA | C7: 13797 | D7: VENETO | E7: VICENZA | F7: Strada Molini 51, Vicenza | G7: Poste Italiane | H7: 1 | I7: 09:30-10:30
A8: 46253 | B8: 243 - VICENZA | C8: FIL. VICENZA | D8: VENETO | E8: VICENZA | F8: Via Cuminello 20, Vicenza | G8: SDA | H8: 1 | I8: 11:00-12:00
A9: 46254 | B9: 028 - VENEZIA | C9: 13118 | D9: VENETO | E9: VENEZIA | F9: Via Torino 88, Venezia Mestre | G9: Poste Italiane | H9: 6 | I9: 14:00-17:30
A10: 46254 | B10: 115 - VENEZIA | C10: 13091 | D10: VENETO | E10: VENEZIA | F10: Viale Alvise Ca' da Mosto 2, Venezia Mestre | G10: Poste Italiane | H10: 3 | I10: 10:30-12:30
A11: 46255 | B11: 225 - PADOVA | C11: PADOVA HUB | D11: VENETO | E11: PADOVA | F11: Via Visco, 1, 35010 Limena PD | G11: SDA | H11: 1 | I11: 10:00-11:00
A12: 46255 | B12: 226 - PADOVA | C12: FIL. PADOVA | D12: VENETO | E12: PADOVA | F12: Via Nuova Zelanda 8, Padova | G12: SDA | H12: 1 | I12: 11:30-12:30
A13: 46258 | B13: 041 - TREVISO | C13: 12549 | D13: VENETO | E13: TREVISO | F13: Piazza della Vittoria 1, Treviso | G13: Poste Italiane | H13: 5 | I13: 12:30-15:30
... A95: 46317 | B95: 102 - ROMA | C95: 10352 | D95: LAZIO | E95: ROMA | F95: Via Dei Crociferi 23, Roma | G95: Poste Italiane | H95: 7 | I95: 08:00-18:00

Sheet Tecnico B
A1: Data | B1: ID Sede | C1: Identificativo Stabile | D1: Regione | E1: Comune | F1: Indirizzo | G1: Gruppo | H1: N. DAE | I1: Fascia Oraria
A2: 46238 | B2: 010 - FARA IN SABINA | C2: FARA IN SABINA | D2: LAZIO | E2: FARA IN SABINA | F2: Via della Chimica, Passo Corese, Fara in Sabina (RI) | G2: PLOG | H2: 2 | I2: 13:30-18:00
A3: 46238 | B3: 190 - RIETI | C3: 10026 | D3: LAZIO | E3: RIETI | F3: Via Tancia 62, Rieti | G3: Poste Italiane | H3: 1 | I3: 11:00-12:00
A4: 46238 | B4: 193 - VITERBO | C4: 302179 | D4: LAZIO | E4: VITERBO | F4: Via dell'Industria 57, Viterbo | G4: Poste Italiane | H4: 1 | I4: 08:00-09:00
A5: 46239 | B5: 145 - ROMA | C5: 10285 | D5: LAZIO | E5: ROMA | F5: Via Affile 103, Roma | G5: Poste Italiane | H5: 2 | I5: 16:00-18:00
A6: 46239 | B6: 148 - ROMA | C6: 26241 | D6: LAZIO | E6: ROMA | F6: Via di Valle Muricana, Roma | G6: Poste Italiane | H6: 2 | I6: 10:30-12:30
A7: 46239 | B7: 178 - ROMA | C7: FIL. ROMA 3 | D7: LAZIO | E7: ROMA | F7: Via Tiberina km 14, Roma | G7: SDA | H7: 2 | I7: 08:00-10:00
A8: 46239 | B8: 180 - ROMA | C8: FIL. ROMA 5 | D8: LAZIO | E8: ROMA | F8: Via Affile 59, Roma | G8: SDA | H8: 2 | I8: 14:00-16:00
A9: 46240 | B9: 058 - ROMA | C9: 10362 | D9: LAZIO | E9: ROMA | F9: Viale degli Eroi di Cefalonia, Roma | G9: Poste Italiane | H9: 4 | I9: 08:00-13:00
A10: 46240 | B10: 146 - ROMA | C10: 10485 | D10: LAZIO | E10: ROMA | F10: Via Amedeo Bocchi, Roma | G10: Poste Italiane | H10: 2 | I10: 14:00-16:00
A11: 46241 | B11: 010 - FARA IN SABINA | C11: FARA IN SABINA | D11: LAZIO | E11: FARA IN SABINA | F11: Via della Chimica, Passo Corese, Fara in Sabina (RI) | G11: PLOG | H11: 6 | I11: 08:00-12:00
A12: 46251 | B12: 113 - PISTOIA | C12: 9241 | D12: TOSCANA | E12: PISTOIA | F12: Via Pratese 49, Pistoia | G12: Poste Italiane | H12: 3 | I12: 13:00-15:00
A13: 46251 | B13: 127 - FIRENZE | C13: 4424 | D13: TOSCANA | E13: FIRENZE | F13: Via della Casella 17, Firenze | G13: Poste Italiane | H13: 2 | I13: 15:30-17:00
... A104: 46318 | B104: 097 - ROMA | C104: 10369 | D104: LAZIO | E104: ROMA | F104: Viale Ferdinando Baldelli 37, Roma | G104: Poste Italiane | H104: 3 | I104: 08:00-12:00

Sheet Tecnico C
A1: Data | B1: Tecnico | C1: ID Sede | D1: Identificativo Stabile | E1: Regione | F1: Comune | G1: Indirizzo | H1: Gruppo | I1: N. DAE | J1: Fascia Oraria | K1: PrimaVisita
A2: 46251 | B2: Tecnico C | C2: 061 - TARANTO | D2: 11441 | E2: PUGLIA | F2: TARANTO | G2: Via Giovinazzi Ciro 78, Taranto | H2: Poste Italiane | I2: 4 | J2: 09:30-15:30 | K2: 1
A3: 46251 | B3: Tecnico C | C3: 202 - TARANTO | D3: 302772 | E3: PUGLIA | F3: TARANTO | G3: Via Angelini Vito, Taranto | H3: Poste Italiane | I3: 1 | J3: 16:00-18:00 | K3: 1
A4: 46252 | B4: Tecnico C | C4: 006 - BARI | D4: 964 | E4: PUGLIA | F4: BARI | G4: Via Amendola Giovanni 116, Bari | H4: Poste Italiane | I4: 6 | J4: 09:00-18:00 | K4: 1
A5: 46253 | B5: Tecnico C | C5: 006 - BARI | D5: 964 | E5: PUGLIA | F5: BARI | G5: Via Amendola Giovanni 116, Bari | H5: Poste Italiane | I5: 4 | J5: 09:00-14:00 | K5: 0
A6: 46253 | B6: Tecnico C | C6: 162 - LECCE | D6: 5749 | E6: PUGLIA | F6: LECCE | G6: Via Lequile 10, Lecce | H6: Poste Italiane | I6: 2 | J6: 15:00-18:00 | K6: 1
A7: 46254 | B7: Tecnico C | C7: 046 - MODUGNO | D7: 970 | E7: PUGLIA | F7: MODUGNO | G7: Statale Provinciale 54 Snc, Modugno | H7: Poste Italiane | I7: 4 | J7: 09:00-13:00 | K7: 1
A8: 46254 | B8: Tecnico C | C8: 046 - MODUGNO | D8: 970 | E8: PUGLIA | F8: MODUGNO | G8: Statale Provinciale 54 Snc, Modugno | H8: Poste Italiane | I8: 2 | J8: 15:00-18:00 | K8: 0
A9: 46255 | B9: Tecnico C | C9: 087 - FOGGIA | D9: 4582 | E9: PUGLIA | F9: FOGGIA | G9: Viale Xxiv Maggio 26, Foggia | H9: Poste Italiane | I9: 3 | J9: 09:00-13:00 | K9: 1
A10: 46255 | B10: Tecnico C | C10: 161 - FOGGIA | D10: 4577 | E10: PUGLIA | F10: FOGGIA | G10: Via Motta Della Regina Snc, Foggia | H10: Poste Italiane | I10: 2 | J10: 15:00-18:00 | K10: 1
A11: 46259 | B11: Tecnico C | C11: 011 - REGGIO DI CALABRIA | D11: 9766 | E11: CALABRIA | F11: REGGIO DI CALABRIA | G11: Strada Statale 18 Primo Tratto 89, Reggio Di Calabria | H11: Poste Italiane | I11: 2 | J11: 15:00-18:00 | K11: 1
A12: 46259 | B12: Tecnico C | C12: 055 - REGGIO DI CALABRIA | D12: 9760 | E12: CALABRIA | F12: REGGIO DI CALABRIA | G12: Via Miraglia Biagio 14, Reggio Di Calabria | H12: Poste Italiane | I12: 4 | J12: 09:00-14:00 | K12: 1
A13: 46260 | B13: Tecnico C | C13: 011 - REGGIO DI CALABRIA | D13: 9766 | E13: CALABRIA | F13: REGGIO DI CALABRIA | G13: Strada Statale 18 Primo Tratto 89, Reggio Di Calabria | H13: Poste Italiane | I13: 5 | J13: 09:00-16:00 | K13: 0
... A17: 46266 | B17: Tecnico C | C17: 027 - PALERMO | D17: 8188 | E17: SICILIA | F17: PALERMO | G17: Via De Gasperi Alcide 103, Palermo | H17: Poste Italiane | I17: 6 | J17: 09:00-18:00 | K17: 1
A18: 02/92/2026 | B18: Tecnico C | C18: 014 - PALERMO | D18: 8236 | E18: SICILIA | F18: PALERMO | G18: Via Monteleone Snc, Palermo | H18: Poste Italiane | I18: 8 | J18: 09:00-18:00 | K18: 1
A19: 46268 | B19: Tecnico C | C19: 108 - PALERMO | D19: 8245 | E19: SICILIA | F19: PALERMO | G19: Viale La Malfa Ugo 177, Palermo | H19: Poste Italiane | I19: 3 | J19: 09:00-13:00 | K19: 1
A20: 46268 | B20: Tecnico C | C20: 053 - PALERMO | D20: 8226 | E20: SICILIA | F20: PALERMO | G20: Via Pirri Rocco 26, Palermo | H20: Poste Italiane | I20: 4 | J20: 14:00-18:00 | K20: 1
A21: 46273 | B21: Tecnico C | C21: 008 - CALTANISSETTA | D21: 2472 | E21: SICILIA | F21: CALTANISSETTA | G21: Via Leone Xiii 12, Caltanissetta | H21: Poste Italiane | I21: 6 | J21: 09:00-18:00 | K21: 1
A22: 46274 | B22: Tecnico C | C22: 008 - CALTANISSETTA | D22: 2472 | E22: SICILIA | F22: CALTANISSETTA | G22: Via Leone Xiii 12, Caltanissetta | H22: Poste Italiane | I22: 2 | J22: 09:00-11:00 | K22: 0
A23: 46274 | B23: Tecnico C | C23: 078 - RAGUSA | D23: 9562 | E23: SICILIA | F23: RAGUSA | G23: Via Ercolano 7, Ragusa | H23: Poste Italiane | I23: 1 | J23: 16:30-18:00 | K23: 1
A24: 46274 | B24: Tecnico C | C24: 203 - FAVARA | D24: 14293 | E24: SICILIA | F24: FAVARA | G24: Contrada San Benedetto Snc, Favara | H24: Poste Italiane | I24: 1 | J24: 12:00-14:00 | K24: 1
A25: 46275 | B25: Tecnico C | C25: 078 - RAGUSA | D25: 9562 | E25: SICILIA | F25: RAGUSA | G25: Via Ercolano 7, Ragusa | H25: Poste Italiane | I25: 3 | J25: 09:00-13:00 | K25: 0
A26: 46275 | B26: Tecnico C | C26: 109 - SIRACUSA | D26: 11293 | E26: SICILIA | F26: SIRACUSA | G26: Viale Santa Panagia 129, Siracusa | H26: Poste Italiane | I26: 3 | J26: 14:00-18:00 | K26: 1
A27: 46286 | B27: Tecnico C | C27: 129 - POTENZA | D27: 300671 | E27: BASILICATA | F27: POTENZA | G27: Via Grippo Pasquale Snc - Edificio Mensa, Potenza | H27: Poste Italiane | I27: 2 | J27: 10:00-13:00 | K27: 1
A28: 46288 | B28: Tecnico C | C28: 073 - CAMPOBASSO | D28: 2521 | E28: MOLISE | F28: CAMPOBASSO | G28: Via San Giovanni 55, Campobasso | H28: Poste Italiane | I28: 4 | J28: 09:00-13:00 | K28: 1
A29: 46288 | B29: Tecnico C | C29: 074 - ISERNIA | D29: 5308 | E29: MOLISE | F29: ISERNIA | G29: Via Xxiv Maggio 243, Isernia | H29: Poste Italiane | I29: 4 | J29: 15:00-18:00 | K29: 1
A30: 46289 | B30: Tecnico C | C30: 130 - AVELLINO | D30: 796 | E30: CAMPANIA | F30: AVELLINO | G30: Via Pianodardine Snc, Avellino | H30: Poste Italiane | I30: 2 | J30: 14:00-18:00 | K30: 1
... A33: 46293 | B33: Tecnico C | C33: 057 - CASERTA | D33: 2693 | E33: CAMPANIA | F33: CASERTA | G33: Via Del Redentore 27, Caserta | H33: Poste Italiane | I33: 4 | J33: 09:30-13:30 | K33: 1
A34: 46293 | B34: Tecnico C | C34: 117 - MADDALONI | D34: FIL. NAPOLI 1 | E34: CAMPANIA | F34: MADDALONI | G34: INTERPORTO MARCIANISE - EDIFICIO LOTTO 14.4, Maddaloni | H34: SDA | I34: 3 | J34: 14:30-18:00 | K34: 1
A35: 46294 | B35: Tecnico C | C35: 123 - NAPOLI | D35: FIL NAPOLI 3 | E35: CAMPANIA | F35: NAPOLI | G35: Ce Naples Dc 3 C/O Interporto Sud Europa Via Boscolagno C/O Interporto Sud Europa – Int.13.5 - 81024 Maddaloni, Napoli | H35: SDA | I35: 3 | J35: 09:00-13:00 | K35: 1
A36: 46294 | B36: Tecnico C | C36: 124 - NAPOLI | D36: FIL NAPOLI 4 | E36: CAMPANIA | F36: NAPOLI | G36: Ce Naples Dc 3 C/O Interporto Sud Europa Via Boscolagno C/O Interporto Sud Europa – Int.13.5 - 81024 Maddaloni, Napoli | H36: SDA | I36: 3 | J36: 14:00-18:00 | K36: 1
A37: 46295 | B37: Tecnico C | C37: 050 - NAPOLI | D37: NAPOLI HUB | E37: CAMPANIA | F37: NAPOLI | G37: Ce Naples Dc 3 C/O Interporto Sud Europa Via Boscolagno C/O Interporto Sud Europa – Int.13.5 - 81024 Maddaloni, Napoli | H37: SDA | I37: 5 | J37: 09:00-15:00 | K37: 1
A38: 46295 | B38: Tecnico C | C38: 186 - NOLA | D38: 301299 | E38: CAMPANIA | F38: NOLA | G38: Via Boscofangone Snc, Nola | H38: Poste Italiane | I38: 1 | J38: 16:30-18:00 | K38: 1
A39: 46296 | B39: Tecnico C | C39: 093 - SALERNO | D39: 10889 | E39: CAMPANIA | F39: SALERNO | G39: Via Paradiso Di Pastena 5, Salerno | H39: Poste Italiane | I39: 3 | J39: 14:30-18:30 | K39: 1
A40: 46296 | B40: Tecnico C | C40: 121 - SALERNO | D40: FIL SALERNO | E40: CAMPANIA | F40: salerno | G40: VIA PACINOTTI - LOC. SCONTRAFATA, Salerno | H40: SDA | I40: 3 | J40: 09:30-13:00 | K40: 1
A41: 46301 | B41: Tecnico C | C41: 077 - MESSINA | D41: 6659 | E41: SICILIA | F41: MESSINA | G41: Strada Statale 114 Km. 5,200 Snc, Messina | H41: Poste Italiane | I41: 4 | J41: 10:00-15:00 | K41: 1
A42: 46301 | B42: Tecnico C | C42: 107 - CATANIA | D42: 2889 | E42: SICILIA | F42: CATANIA | G42: Via Ferrari Enzo 30, Catania | H42: Poste Italiane | I42: 3 | J42: 16:00-18:00 | K42: 1
A43: 46302 | B43: Tecnico C | C43: 088 - CATANIA | D43: 2890 | E43: SICILIA | F43: CATANIA | G43: Via Etnea - Pal. Poste 215, Catania | H43: Poste Italiane | I43: 3 | J43: 09:00-13:00 | K43: 1
A44: 46314 | B44: Tecnico C | C44: 092 - NAPOLI | D44: 7493 | E44: CAMPANIA | F44: NAPOLI | G44: Via Montagna Spaccata 2, Napoli | H44: Poste Italiane | I44: 3 | J44: 10:00-14:00 | K44: 1
A45: 46314 | B45: Tecnico C | C45: 133 - NAPOLI | D45: 7431 | E45: CAMPANIA | F45: NAPOLI | G45: Via Baku' 2, Napoli | H45: Poste Italiane | I45: 2 | J45: 15:30-18:00 | K45: 1
...

Sheet 1°Preparazione
A1: Data | B1: Tecnico | C1: ID Sede | D1: Identificativo Stabile | E1: Regione | F1: Comune | G1: Indirizzo | H1: Gruppo | I1: N. DAE | J1: Fascia Oraria | K1: Settimana | M1: Totale preparati: | N1: =SUM(I2:I51) -> 145
A2: 46251 | B2: Tecnico A | C2: 019 - VERONA | D2: 13472 | E2: VENETO | F2: VERONA | G2: Via delle Coste, Verona | H2: Poste Italiane | I2: 6 | J2: 10:00-13:30 | K2: 1
A3: 46251 | B3: Tecnico B | C3: 113 - PISTOIA | D3: 9241 | E3: TOSCANA | F3: PISTOIA | G3: Via Pratese 49, Pistoia | H3: Poste Italiane | I3: 3 | J3: 13:00-15:00 | K3: 1
A4: 46251 | B4: Tecnico B | C4: 127 - FIRENZE | D4: 4424 | E4: TOSCANA | F4: FIRENZE | G4: Via della Casella 17, Firenze | H4: Poste Italiane | I4: 2 | J4: 15:30-17:00 | K4: 1
A5: 46252 | B5: Tecnico B | C5: 009 - SESTO FIORENTINO | D5: 14730 | E5: TOSCANA | F5: SESTO FIORENTINO | G5: Via Pier Paolo Pasolini 397, Sesto Fiorentino | H5: Poste Italiane | I5: 9 | J5: 08:30-13:30 | K5: 1
A6: 46252 | B6: Tecnico A | C6: 029 - VERONA | D6: 13510 | E6: VENETO | F6: VERONA | G6: Piazzale XXV Aprile 4/A, Verona | H6: Poste Italiane | I6: 6 | J6: 09:00-12:30 | K6: 1
A7: 46252 | B7: Tecnico B | C7: 110 - FIRENZE | D7: 4441 | E7: TOSCANA | F7: FIRENZE | G7: Via del Mezzetta, Firenze | H7: Poste Italiane | I7: 3 | J7: 15:00-17:00 | K7: 1
A8: 46252 | B8: Tecnico A | C8: 183 - VERONA | D8: FIL. VERONA | E8: VENETO | F8: VERONA | G8: Strada dell'Alpo 54/A, Verona | H8: SDA | I8: 2 | J8: 14:00-15:30 | K8: 1
A9: 46252 | B9: Tecnico A | C9: 185 - VERONA | D9: VERONA | E9: VENETO | F9: VERONA | G9: Via dell'Elettronica 6, Verona | H9: Postel | I9: 2 | J9: 16:00-17:30 | K9: 1
A10: 46253 | B10: Tecnico B | C10: 018 - FIRENZE | D10: 4444 | E10: TOSCANA | F10: FIRENZE | G10: Piazza Davanzati 4, Firenze | H10: Poste Italiane | I10: 6 | J10: 13:30-17:00 | K10: 1
A11: 46253 | B11: Tecnico B | C11: 048 - PRATO | D11: 9530 | E11: TOSCANA | F11: PRATO | G11: Via Arcivescovo Antonio Martini 54, Prato | H11: Poste Italiane | I11: 5 | J11: 08:30-11:30 | K11: 1
A12: 46253 | B12: Tecnico A | C12: 049 - PADOVA | D12: 8027 | E12: VENETO | F12: PADOVA | G12: Via della Ricerca Scientifica 5, Padova | H12: Poste Italiane | I12: 6 | J12: 13:30-17:00 | K12: 1
A13: 46253 | B13: Tecnico A | C13: 206 - VICENZA | D13: 13797 | E13: VENETO | F13: VICENZA | G13: Strada Molini 51, Vicenza | H13: Poste Italiane | I13: 1 | J13: 09:30-10:30 | K13: 1
... A51: 46265 | B51: Tecnico B | C51: 229 - PESARO | D51: FIL. PESARO | E51: MARCHE | F51: PESARO | G51: Strada dei Cacciatori 42, Pesaro | H51: SDA | I51: 1 | J51: 16:00-17:00 | K51: 2

Sheet Preparazinoe Tecnico C
A1: Data | B1: Tecnico | C1: ID Sede | D1: Identificativo Stabile | E1: Regione | F1: Comune | G1: Indirizzo | H1: Gruppo | I1: N. DAE | J1: Fascia Oraria | K1: PrimaVisita | M1: Totale preparati: | O1: =SUM(I2:I26) -> 84
A2: 46251 | B2: Tecnico C | C2: 006 - BARI | D2: 964 | E2: PUGLIA | F2: BARI | G2: Via Amendola Giovanni 116, Bari | H2: Poste Italiane | I2: 6 | J2: 09:00-18:00 | K2: 1
A3: 46252 | B3: Tecnico C | C3: 006 - BARI | D3: 964 | E3: PUGLIA | F3: BARI | G3: Via Amendola Giovanni 116, Bari | H3: Poste Italiane | I3: 4 | J3: 09:00-14:00 | K3: 0
A4: 46252 | B4: Tecnico C | C4: 046 - MODUGNO | D4: 970 | E4: PUGLIA | F4: MODUGNO | G4: Statale Provinciale 54 Snc, Modugno | H4: Poste Italiane | I4: 2 | J4: 15:00-18:00 | K4: 1
A5: 46253 | B5: Tecnico C | C5: 046 - MODUGNO | D5: 970 | E5: PUGLIA | F5: MODUGNO | G5: Statale Provinciale 54 Snc, Modugno | H5: Poste Italiane | I5: 4 | J5: 09:00-13:00 | K5: 0
A6: 46253 | B6: Tecnico C | C6: 162 - LECCE | D6: 5749 | E6: PUGLIA | F6: LECCE | G6: Via Lequile 10, Lecce | H6: Poste Italiane | I6: 2 | J6: 15:00-18:00 | K6: 1
A7: 46254 | B7: Tecnico C | C7: 061 - TARANTO | D7: 11441 | E7: PUGLIA | F7: TARANTO | G7: Via Giovinazzi Ciro 78, Taranto | H7: Poste Italiane | I7: 4 | J7: 09:30-15:30 | K7: 1
A8: 46254 | B8: Tecnico C | C8: 202 - TARANTO | D8: 302772 | E8: PUGLIA | F8: TARANTO | G8: Via Angelini Vito, Taranto | H8: Poste Italiane | I8: 1 | J8: 16:00-18:00 | K8: 1
A9: 46255 | B9: Tecnico C | C9: 087 - FOGGIA | D9: 4582 | E9: PUGLIA | F9: FOGGIA | G9: Viale Xxiv Maggio 26, Foggia | H9: Poste Italiane | I9: 3 | J9: 09:00-13:00 | K9: 1
A10: 46255 | B10: Tecnico C | C10: 161 - FOGGIA | D10: 4577 | E10: PUGLIA | F10: FOGGIA | G10: Via Motta Della Regina Snc, Foggia | H10: Poste Italiane | I10: 2 | J10: 15:00-18:00 | K10: 1
A11: 46259 | B11: Tecnico C | C11: 011 - REGGIO DI CALABRIA | D11: 9766 | E11: CALABRIA | F11: REGGIO DI CALABRIA | G11: Strada Statale 18 Primo Tratto 89, Reggio Di Calabria | H11: Poste Italiane | I11: 2 | J11: 15:00-18:00 | K11: 1
A12: 46259 | B12: Tecnico C | C12: 055 - REGGIO DI CALABRIA | D12: 9760 | E12: CALABRIA | F12: REGGIO DI CALABRIA | G12: Via Miraglia Biagio 14, Reggio Di Calabria | H12: Poste Italiane | I12: 4 | J12: 09:00-14:00 | K12: 1
A13: 46260 | B13: Tecnico C | C13: 011 - REGGIO DI CALABRIA | D13: 9766 | E13: CALABRIA | F13: REGGIO DI CALABRIA | G13: Strada Statale 18 Primo Tratto 89, Reggio Di Calabria | H13: Poste Italiane | I13: 5 | J13: 09:00-16:00 | K13: 0
... A26: 46275 | B26: Tecnico C | C26: 109 - SIRACUSA | D26: 11293 | E26: SICILIA | F26: SIRACUSA | G26: Viale Santa Panagia 129, Siracusa | H26: Poste Italiane | I26: 3 | J26: 14:00-18:00 | K26: 1

Sheet 2°Preparazione (25-ago)
A1: Data | B1: Tecnico | C1: ID Sede | D1: Identificativo Stabile | E1: Regione | F1: Comune | G1: Indirizzo | H1: Gruppo | I1: N. DAE | J1: Fascia Oraria | K1: PrimaVisita | M1: Totale preparati: | N1: 112
A2: 46266 | B2: Tecnico A | C2: 003 - CHIARI | D2: CHIARI | E2: LOMBARDIA | F2: CHIARI | G2: Via Sam Quilleri 1, Chiari BS | H2: PLOG | I2: 9 | J2: 11:30-17:30 | K2: =IF(COUNTIFS($C$2:C2,C2)=1,1,0) -> 1
A3: 46266 | B3: Tecnico A | C3: 065 - BRESCIA | D3: 15947 | E3: LOMBARDIA | F3: BRESCIA | G3: Via Dalmazia 13, Brescia | H3: Poste Italiane | I3: 4 | J3: 08:30-11:00 | K3: =IF(COUNTIFS($C$2:C3,C3)=1,1,0) -> 1
A4: 46266 | B4: Tecnico B | C4: 072 - ANCONA | D4: 323 | E4: MARCHE | F4: ANCONA | G4: Via Cameranense 335/C, Ancona | H4: Poste Italiane | I4: 4 | J4: 10:30-13:00 | K4: =IF(COUNTIFS($C$2:C4,C4)=1,1,0) -> 1
A5: 46266 | B5: Tecnico B | C5: 086 - ANCONA | D5: 340 | E5: MARCHE | F5: ANCONA | G5: Largo XXIV Maggio 2, Ancona | H5: Poste Italiane | I5: 3 | J5: 08:30-10:30 | K5: =IF(COUNTIFS($C$2:C5,C5)=1,1,0) -> 1
A6: 46266 | B6: Tecnico B | C6: 168 - ANCONA | D6: FIL. ANCONA | E6: MARCHE | F6: ANCONA | G6: Via Carotti, Ancona | H6: SDA | I6: 2 | J6: 14:30-16:00 | K6: =IF(COUNTIFS($C$2:C6,C6)=1,1,0) -> 1
A7: 46266 | B7: Tecnico B | C7: 220 - civitanova | D7: FIL CIVITANOVA MARCHE | E7: MARCHE | F7: civitanova | G7: Via Enzo Ferrari 79, Civitanova Marche | H7: SDA | I7: 1 | J7: 17:00-18:00 | K7: =IF(COUNTIFS($C$2:C7,C7)=1,1,0) -> 1
A8: 46267 | B8: Tecnico A | C8: 003 - CHIARI | D8: CHIARI | E8: LOMBARDIA | F8: CHIARI | G8: Via Sam Quilleri 1, Chiari BS | H8: PLOG | I8: 8 | J8: 08:30-13:00 | K8: =IF(COUNTIFS($C$2:C8,C8)=1,1,0) -> 0
A9: 46267 | B9: Tecnico A | C9: 059 - BERGAMO | D9: 1355 | E9: LOMBARDIA | F9: BERGAMO | G9: Via Matris Domini 2, Bergamo | H9: Poste Italiane | I9: 4 | J9: 15:00-17:30 | K9: =IF(COUNTIFS($C$2:C9,C9)=1,1,0) -> 1
A10: 46267 | B10: Tecnico B | C10: 157 - ASCOLI PICENO | D10: 593 | E10: MARCHE | F10: ASCOLI PICENO | G10: Via del Commercio 13, Ascoli Piceno | H10: Poste Italiane | I10: 2 | J10: 14:30-16:30 | K10: =IF(COUNTIFS($C$2:C10,C10)=1,1,0) -> 1
A11: 46267 | B11: Tecnico B | C11: 198 - MACERATA | D11: 6236 | E11: MARCHE | F11: MACERATA | G11: Via Annibali 108, Macerata | H11: Poste Italiane | I11: 1 | J11: 08:30-09:30 | K11: =IF(COUNTIFS($C$2:C11,C11)=1,1,0) -> 1
A12: 46267 | B12: Tecnico B | C12: 200 - PORTO SAN GIORGIO | D12: 4244 | E12: MARCHE | F12: PORTO SAN GIORGIO | G12: Via Thomas Alva Edison, Porto San Giorgio | H12: Poste Italiane | I12: 1 | J12: 10:30-11:30 | K12: =IF(COUNTIFS($C$2:C12,C12)=1,1,0) -> 1
A13: 46267 | B13: Tecnico B | C13: 210 - PORTO D'ASCOLI | D13: FIL. PORTO D'ASCOLI | E13: MARCHE | F13: PORTO D'ASCOLI | G13: Via del Lavoro 21, Centobuchi, Monteprandone (AP) | H13: SDA | I13: 1 | J13: 13:00-14:00 | K13: =IF(COUNTIFS($C$2:C13,C13)=1,1,0) -> 1
... A33: 46276 | B33: Tecnico A | C33: 002 - VIDIGULFO | D33: VIDIGULFO A e B | E33: LOMBARDIA | F33: VIDIGULFO | G33: Via delle Industrie 3, Vidigulfo PV | H33: PLOG | I33: 7 | J33: 08:30-12:30 | K33: =IF(COUNTIFS($C$2:C33,C33)=1,1,0) -> 0

Sheet 3°Preparazione (8-sett)
A1: Data | B1: Tecnico | C1: ID Sede | D1: Identificativo Stabile | E1: Regione | F1: Comune | G1: Indirizzo | H1: Gruppo | I1: N. DAE | J1: Fascia Oraria | K1: PrimaVisita | N1: Totale preparati: | O1: =SUM(I2:I44) -> 135
A2: 46279 | B2: Tecnico B | C2: 138 - CARPI | D2: 7089 | E2: EMILIA ROMAGNA | F2: CARPI | G2: Via Cesare Battisti 3, Carpi | H2: Poste Italiane | I2: 2 | J2: 10:30-12:00 | K2: =IF(COUNTIFS($C$2:C2,C2)=1,1,0) -> 1
A3: 46279 | B3: Tecnico B | C3: 141 - MODENA | D3: 7151 | E3: EMILIA ROMAGNA | F3: MODENA | G3: Via delle Nazioni 125, Modena | H3: Poste Italiane | I3: 2 | J3: 13:30-15:00 | K3: =IF(COUNTIFS($C$2:C3,C3)=1,1,0) -> 1
A4: 46279 | B4: Tecnico A | C4: 155 - PAVIA | D4: 8506 | E4: LOMBARDIA | F4: PAVIA | G4: Via Brambilla 1, Pavia | H4: Poste Italiane | I4: 2 | J4: 14:30-16:00 | K4: =IF(COUNTIFS($C$2:C4,C4)=1,1,0) -> 1
A5: 46279 | B5: Tecnico B | C5: 175 - MODENA | D5: FIL. MODENA | E5: EMILIA ROMAGNA | F5: MODENA | G5: Via Gabriele D'Annunzio 190, Modena | H5: SDA | I5: 2 | J5: 15:30-17:00 | K5: =IF(COUNTIFS($C$2:C5,C5)=1,1,0) -> 1
A6: 46279 | B6: Tecnico A | C6: 228 - PAVIA | D6: FIL. PAVIA | E6: LOMBARDIA | F6: PAVIA | G6: Via della Meccanica 4, Pavia | H6: SDA | I6: 1 | J6: 16:30-17:30 | K6: =IF(COUNTIFS($C$2:C6,C6)=1,1,0) -> 1
A7: 46280 | B7: Tecnico A | C7: 015 - landriano | D7: HUB NORD LANDRIANO | E7: LOMBARDIA | F7: landriano | G7: Via Privata Paolo Baffi, Landriano PV | H7: SDA | I7: 7 | J7: 08:30-12:30 | K7: =IF(COUNTIFS($C$2:C7,C7)=1,1,0) -> 1
A8: 46280 | B8: Tecnico A | C8: 070 - PESCHIERA BORROMEO | D8: 7001 | E8: LOMBARDIA | F8: PESCHIERA BORROMEO | G8: Via Archimede 2, Peschiera Borromeo | H8: Poste Italiane | I8: 5 | J8: 14:30-17:30 | K8: =IF(COUNTIFS($C$2:C8,C8)=1,1,0) -> 1
A9: 46280 | B9: Tecnico B | C9: 094 - PARMA | D9: 15716 | E9: EMILIA ROMAGNA | F9: PARMA | G9: Strada Pastrengo 1, Parma | H9: Poste Italiane | I9: 4 | J9: 11:30-16:00 | K9: =IF(COUNTIFS($C$2:C9,C9)=1,1,0) -> 1
A10: 46280 | B10: Tecnico B | C10: 187 - REGGIO NELL'EMILIA | D10: 9908 | E10: EMILIA ROMAGNA | F10: REGGIO NELL'EMILIA | G10: Via Piccard 14, Reggio Emilia | H10: Poste Italiane | I10: 1 | J10: 10:00-11:00 | K10: =IF(COUNTIFS($C$2:C10,C10)=1,1,0) -> 1
A11: 46280 | B11: Tecnico B | C11: 227 - PARMA | D11: FIL. PARMA | E11: EMILIA ROMAGNA | F11: PARMA | G11: Via Alfredo Veroni 27/A, Parma | H11: SDA | I11: 1 | J11: 16:30-17:30 | K11: =IF(COUNTIFS($C$2:C11,C11)=1,1,0) -> 1
A12: 46280 | B12: Tecnico B | C12: 233 - REGGIO EMILIA | D12: FIL. REGGIO EMILIA | E12: EMILIA ROMAGNA | F12: REGGIO emilia | G12: Via Natta 6, Reggio Emilia | H12: SDA | I12: 1 | J12: 08:30-09:30 | K12: =IF(COUNTIFS($C$2:C12,C12)=1,1,0) -> 1
A13: 46281 | B13: Tecnico B | C13: 031 - PIACENZA | D13: PIACENZA HUB CASTEL SAN GIOVANNI | E13: EMILIA ROMAGNA | F13: piacenza | G13: Via della Cascinetta snc, Piacenza | H13: SDA | I13: 6 | J13: 08:30-12:00 | K13: =IF(COUNTIFS($C$2:C13,C13)=1,1,0) -> 1
... A44: 46290 | B44: Tecnico C | C44: 056 - AVELLINO | D44: 786 | E44: CAMPANIA | F44: AVELLINO | G44: Via De Sanctis Francesco 3, Avellino | H44: Poste Italiane | I44: 4 | J44: 09:00-13:00 | K44: =IF(COUNTIFS($C$2:C44,C44)=1,1,0) -> 1

Sheet 4°Preparazione (21-sett)
A1: Data | B1: Tecnico | C1: ID Sede | D1: Identificativo Stabile | E1: Regione | F1: Comune | G1: Indirizzo | H1: Gruppo | I1: N. DAE | J1: Fascia Oraria | K1: PrimaVisita | M1: Totale preparati | N1: =SUM(I2:I55) -> 149
A2: 46293 | B2: Tecnico B | C2: 044 - BOLOGNA | D2: 1733 | E2: EMILIA ROMAGNA | F2: BOLOGNA | G2: Via Francesco Zanardi 32, Bologna | H2: Poste Italiane | I2: 5 | J2: 11:00-14:00 | K2: =IF(COUNTIFS($C$2:C2,C2)=1,1,0) -> 1
A3: 46293 | B3: Tecnico C | C3: 057 - CASERTA | D3: 2693 | E3: CAMPANIA | F3: CASERTA | G3: Via Del Redentore 27, Caserta | H3: Poste Italiane | I3: 4 | J3: 09:30-13:30 | K3: =IF(COUNTIFS($C$2:C3,C3)=1,1,0) -> 1
A4: 46293 | B4: Tecnico C | C4: 117 - MADDALONI | D4: FIL. NAPOLI 1 | E4: CAMPANIA | F4: MADDALONI | G4: INTERPORTO MARCIANISE - EDIFICIO LOTTO 14.4, Maddaloni | H4: SDA | I4: 3 | J4: 14:30-18:00 | K4: =IF(COUNTIFS($C$2:C4,C4)=1,1,0) -> 1
A5: 46293 | B5: Tecnico B | C5: 170 - BOLOGNA | D5: FIL. BOLOGNA | E5: EMILIA ROMAGNA | F5: BOLOGNA | G5: Interporto di Bologna, Comparto 13.5, Bentivoglio (BO) | H5: SDA | I5: 2 | J5: 15:30-17:00 | K5: =IF(COUNTIFS($C$2:C5,C5)=1,1,0) -> 1
A6: 46293 | B6: Tecnico A | C6: 172 - MILANO | D6: FIL. MILANO 1 | E6: LOMBARDIA | F6: MILANO | G6: Via Fantoli 30, Milano | H6: SDA | I6: 2 | J6: 10:00-11:30 | K6: =IF(COUNTIFS($C$2:C6,C6)=1,1,0) -> 1
A7: 46293 | B7: Tecnico A | C7: 173 - MILANO | D7: FIL. MILANO 2 | E7: LOMBARDIA | F7: MILANO | G7: Via delle Industrie 9, Milano | H7: SDA | I7: 2 | J7: 12:00-13:30 | K7: =IF(COUNTIFS($C$2:C7,C7)=1,1,0) -> 1
A8: 46293 | B8: Tecnico A | C8: 221 - MILANO | D8: FIL. MILANO 3 | E8: LOMBARDIA | F8: MILANO | G8: Via delle Azalee 6/A, Milano | H8: SDA | I8: 1 | J8: 15:00-16:00 | K8: =IF(COUNTIFS($C$2:C8,C8)=1,1,0) -> 1
A9: 46293 | B9: Tecnico A | C9: 222 - MILANO | D9: FIL. MILANO 4 | E9: LOMBARDIA | F9: MILANO | G9: Via dei Rovedi, Milano | H9: SDA | I9: 1 | J9: 17:00-18:00 | K9: =IF(COUNTIFS($C$2:C9,C9)=1,1,0) -> 1
A10: 46294 | B10: Tecnico B | C10: 030 - BOLOGNA | D10: BOLOGNA HUB 13.4 | E10: EMILIA ROMAGNA | F10: BOLOGNA | G10: Viale della Logistica snc, Bologna | H10: SDA | I10: 6 | J10: 08:30-12:00 | K10: =IF(COUNTIFS($C$2:C10,C10)=1,1,0) -> 1
A11: 46294 | B11: Tecnico B | C11: 116 - BOLOGNA | D11: BOLOGNA HUB 13.10 | E11: EMILIA ROMAGNA | F11: BOLOGNA | G11: Interporto di Bologna, Blocco 13.10, Bentivoglio (BO) | H11: SDA | I11: 3 | J11: 14:30-16:30 | K11: =IF(COUNTIFS($C$2:C11,C11)=1,1,0) -> 1 | L11: AED a cui è stata cambiata l'ora il 30/06/2026
A12: 46294 | B12: Tecnico C | C12: 123 - NAPOLI | D12: FIL NAPOLI 3 | E12: CAMPANIA | F12: NAPOLI | G12: Ce Naples Dc 3 C/O Interporto Sud Europa Via Boscolagno C/O Interporto Sud Europa – Int.13.5 - 81024 Maddaloni, Napoli | H12: SDA | I12: 3 | J12: 09:00-13:00 | K12: =IF(COUNTIFS($C$2:C12,C12)=1,1,0) -> 1
A13: 46294 | B13: Tecnico C | C13: 124 - NAPOLI | D13: FIL NAPOLI 4 | E13: CAMPANIA | F13: NAPOLI | G13: Ce Naples Dc 3 C/O Interporto Sud Europa Via Boscolagno C/O Interporto Sud Europa – Int.13.5 - 81024 Maddaloni, Napoli | H13: SDA | I13: 3 | J13: 14:00-18:00 | K13: =IF(COUNTIFS($C$2:C13,C13)=1,1,0) -> 1
A14: 46294 | B14: Tecnico A | C14: 160 - NOVARA | D14: 7669 | E14: PIEMONTE | F14: NOVARA | G14: Via Monte Rosa 101, Novara | H14: Poste Italiane | I14: 2 | J14: 15:30-17:00 | K14: =IF(COUNTIFS($C$2:C14,C14)=1,1,0) -> 1
A15: 46294 | B15: Tecnico B | C15: 212 - BOLOGNA | D15: FIL. BOLOGNA NEW | E15: EMILIA ROMAGNA | F15: BOLOGNA | G15: Interporto di Bologna, Comparto 4.3, Bentivoglio (BO) | H15: SDA | I15: 1 | J15: 13:30-14:30 | K15: =IF(COUNTIFS($C$2:C15,C15)=1,1,0) -> 1
A16: 46294 | B16: Tecnico B | C16: 213 - BOLOGNA | D16: BOLOGNA BANCHE | E16: EMILIA ROMAGNA | F16: BOLOGNA | G16: Via Verde 6, Bologna | H16: SDA | I16: 1 | J16: 17:00-18:00 | K16: =IF(COUNTIFS($C$2:C16,C16)=1,1,0) -> 1
A17: 46294 | B17: Tecnico A | C17: 224 - NOVARA | D17: FIL. NOVARA | E17: PIEMONTE | F17: NOVARA | G17: Via Guido Rossa 2, Veveri, Novara | H17: SDA | I17: 1 | J17: 14:00-15:00 | K17: =IF(COUNTIFS($C$2:C17,C17)=1,1,0) -> 1
A18: 46294 | B18: Tecnico A | C18: 241 - MILANO | D18: MILANO MALPENSA II | E18: LOMBARDIA | F18: MILANO | G18: Avioport Logistics Park, Via del Gregge 100, Lonate Pozzolo | H18: SDA | I18: 1 | J18: 11:30-12:30 | K18: =IF(COUNTIFS($C$2:C18,C18)=1,1,0) -> 1
A19: 46294 | B19: Tecnico A | C19: 242 - MILANO | D19: MILANO GATEWAY | E19: LOMBARDIA | F19: MILANO | G19: Via Bassano del Grappa, Milano | H19: SDA | I19: 1 | J19: 09:00-10:30 | K19: =IF(COUNTIFS($C$2:C19,C19)=1,1,0) -> 1
A20: 46295 | B20: Tecnico B | C20: 032 - CASTEL SAN GIOVANNI | D20: CASTEL SAN GIOVANNI Y2 | E20: EMILIA ROMAGNA | F20: CASTEL SAN GIOVANNI | G20: Via del Colombarone, Castel San Giovanni (PC) | H20: PLOG | I20: 6 | J20: 10:00-13:30 | K20: =IF(COUNTIFS($C$2:C20,C20)=1,1,0) -> 1
A21: 46295 | B21: Tecnico A | C21: 039 - TORINO | D21: 11958 | E21: PIEMONTE | F21: TORINO | G21: Via Vittorio Alfieri 10, Torino | H21: Poste Italiane | I21: 5 | J21: 13:30-16:30 | K21: =IF(COUNTIFS($C$2:C21,C21)=1,1,0) -> 1
A22: 46295 | B22: Tecnico C | C22: 050 - NAPOLI | D22: NAPOLI HUB | E22: CAMPANIA | F22: NAPOLI | G22: Ce Naples Dc 3 C/O Interporto Sud Europa Via Boscolagno C/O Interporto Sud Europa – Int.13.5 - 81024 Maddaloni, Napoli | H22: SDA | I22: 5 | J22: 09:00-15:00 | K22: =IF(COUNTIFS($C$2:C22,C22)=1,1,0) -> 1
A23: 46295 | B23: Tecnico B | C23: 118 - PIACENZA | D23: PIACENZA HUB BULKY | E23: EMILIA ROMAGNA | F23: piacenza | G23: Strada Dogana Po 2, Piacenza | H23: SDA | I23: 3 | J23: 15:00-17:00 | K23: =IF(COUNTIFS($C$2:C23,C23)=1,1,0) -> 1
... A55: 46304 | B55: Tecnico B | C55: 037 - GENOVA | D55: 4951 | E55: LIGURIA | F55: GENOVA | G55: Piazza del Monastero 4, Genova | H55: Poste Italiane | I55: 5 | J55: 08:30-11:30 | K55: =IF(COUNTIFS($C$2:C55,C55)=1,1,0) -> 1

Sheet 5°Preparazione (5-ott)
A1: Data | B1: Tecnico | C1: ID Sede | D1: Identificativo Stabile | E1: Regione | F1: Comune | G1: Indirizzo | H1: Gruppo | I1: N. DAE | J1: Fascia Oraria | K1: PrimaVisita | N1: Totale preparati: | O1: =SUM(I2:I32) -> 100
A2: 46307 | B2: Tecnico A | C2: 064 - SAVONA | D2: 11139 | E2: LIGURIA | F2: SAVONA | G2: Piazza Aldo Moro 6, Savona | H2: Poste Italiane | I2: 4 | J2: 14:30-17:00 | K2: =IF(COUNTIFS($C$2:C2,C2)=1,1,0) -> 1
A3: 46308 | B3: Tecnico B | C3: 081 - POMEZIA | D3: POMEZIA | E3: LAZIO | F3: POMEZIA | G3: Via Campobello 43, Pomezia | H3: Postel | I3: 4 | J3: 15:00-18:00 | K3: =IF(COUNTIFS($C$2:C3,C3)=1,1,0) -> 1
A4: 46308 | B4: Tecnico B | C4: 144 - FROSINONE | D4: 4782 | E4: LAZIO | F4: FROSINONE | G4: Via Don Minzoni 16, Frosinone | H4: Poste Italiane | I4: 2 | J4: 08:00-12:00 | K4: =IF(COUNTIFS($C$2:C4,C4)=1,1,0) -> 1
A5: 46308 | B5: Tecnico A | C5: 149 - IMPERIA | D5: 5227 | E5: LIGURIA | F5: IMPERIA | G5: Via Spontone 39, Imperia | H5: Poste Italiane | I5: 2 | J5: 08:30-10:00 | K5: =IF(COUNTIFS($C$2:C5,C5)=1,1,0) -> 1
A6: 46308 | B6: Tecnico A | C6: 153 - MILANO | D6: 6911 | E6: LOMBARDIA | F6: MILANO | G6: Piazzale Lugano 15, Milano | H6: Poste Italiane | I6: 2 | J6: 14:30-16:00 | K6: =IF(COUNTIFS($C$2:C6,C6)=1,1,0) -> 1
A7: 46308 | B7: Tecnico B | C7: 189 - LATINA | D7: 5643 | E7: LAZIO | F7: LATINA | G7: Via Rossetti 28, Latina | H7: Poste Italiane | I7: 1 | J7: 12:00-14:00 | K7: =IF(COUNTIFS($C$2:C7,C7)=1,1,0) -> 1
A8: 46309 | B8: Tecnico B | C8: 033 - POMEZIA | D8: POMEZIA | E8: LAZIO | F8: POMEZIA | G8: Via delle Monachelle, Pomezia | H8: PLOG | I8: 6 | J8: 11:00-18:00 | K8: =IF(COUNTIFS($C$2:C8,C8)=1,1,0) -> 1
A9: 46309 | B9: Tecnico A | C9: 060 - MILANO | D9: 6896 | E9: LOMBARDIA | F9: MILANO | G9: Via Guglielmo da Velate 11, Milano | H9: Poste Italiane | I9: 4 | J9: 08:30-11:00 | K9: =IF(COUNTIFS($C$2:C9,C9)=1,1,0) -> 1
A10: 46309 | B10: Tecnico A | C10: 068 - MILANO | D10: 6901 | E10: LOMBARDIA | F10: MILANO | G10: Via Benozzo Gozzoli 51, Milano | H10: Poste Italiane | I10: 4 | J10: 13:00-15:30 | K10: =IF(COUNTIFS($C$2:C10,C10)=1,1,0) -> 1
A11: 46309 | B11: Tecnico B | C11: 234 - ROMA | D11: FIL. ROMA 2 | E11: LAZIO | F11: ROMA | G11: Via Laurentina km 23,500, Roma | H11: SDA | I11: 1 | J11: 08:00-10:00 | K11: =IF(COUNTIFS($C$2:C11,C11)=1,1,0) -> 1
A12: 46310 | B12: Tecnico B | C12: 051 - ROMA | D12: ROMA HUB PASSO CORESE | E12: LAZIO | F12: ROMA | G12: Viale della Logistica, Santa Palomba, Roma | H12: SDA | I12: 5 | J12: 12:00-18:00 | K12: =IF(COUNTIFS($C$2:C12,C12)=1,1,0) -> 1
A13: 46310 | B13: Tecnico B | C13: 119 - ROMA | D13: ROMA HUB BULKY | E13: LAZIO | F13: ROMA | G13: Via della Meccanica, Santa Palomba, Roma | H13: SDA | I13: 2 | J13: 08:00-12:00 | K13: =IF(COUNTIFS($C$2:C13,C13)=1,1,0) -> 1
... A32: 46318 | B32: Tecnico B | C32: 097 - ROMA | D32: 10369 | E32: LAZIO | F32: ROMA | G32: Viale Ferdinando Baldelli 37, Roma | H32: Poste Italiane | I32: 3 | J32: 08:00-12:00 | K32: =IF(COUNTIFS($C$2:C32,C32)=1,1,0) -> 1
